Workbook

Sheet Design
A1: Samples | B1: B (mm) | C1: L (mm) | D1: H (mm) | E1: Numbers
A2: Cubes | B2: 100 | C2: 100 | D2: 100 | E2: 15
A3: Cylinder | B3: 10 | D3: 20 | E3: 3
A4: Beams | B4: 100 | C4: 100 | D4: 350 | E4: 1
B7: 0 | C7: 0.01 | D7: 0.02 | E7: 0.03 | F7: 0.04 | G7: 0.05
A8: Cement (kg) | B8: 19.936 | C8: 19.936 | D8: 19.936 | E8: 19.936 | F8: 19.936 | G8: 19.936
A9: Fine Aggregates (kg) | B9: 33.226 | C9: 33.226 | D9: 33.226 | E9: 33.226 | F9: 33.226 | G9: 33.226
A10: Coarse aggregates (kg) | B10: 0.155 | C10: 0.155 | D10: 0.155 | E10: 0.155 | F10: 0.155 | G10: 0.155
A11: Superplasticizer (kg) | B11: 5.419 | C11: 5.419 | D11: 5.419 | E11: 5.419 | F11: 5.419 | G11: 5.419
A12: Water (kg) | B12: 5.419 | C12: 5.419 | D12: 5.419 | E12: 5.419 | F12: 5.419 | G12: 5.419
A13: Aluminum powder (kg) | B13: 0 | C13: 0.155 | D13: =C13*2 -> 0.31 | E13: =C13*3 -> 0.465 | F13: =C13*4 -> 0.62 | G13: =C13*5 -> 0.775

Sheet Compression
B1: 00Al | D1: 01Al | F1: 02Al | H1: 03Al | J1: 04Al | L1: 05Al
A2: Slump (mm) | D2: 150 | F2: 152 | H2: 153 | J2: 151 | L2: 151
A4: DENSITY
A5: 7 | B5: 2376 | C5: =AVERAGE(B5:B7)/1000 -> 2.365 | D5: 2332 | E5: =AVERAGE(D5:D7)/1000 -> 2.3283333 | F5: 2297 | G5: =AVERAGE(F5:F7)/1000 -> 2.296 | H5: 2264 | I5: =AVERAGE(H5:H7)/1000 -> 2.2606667 | J5: 2135 | K5: =AVERAGE(J5:J7)/1000 -> 2.1416667 | L5: 2228 | M5: =AVERAGE(L5:L7)/1000 -> 2.2176667
B6: 2353 | D6: 2330 | F6: 2301 | H6: 2278 | J6: 2150 | L6: 2215
B7: 2366 | D7: 2323 | F7: 2290 | H7: 2240 | J7: 2140 | L7: 2210
A8: 14 | B8: 2465 | C8: =AVERAGE(B8:B10)/1000 -> 2.4693333 | D8: 2266 | E8: =AVERAGE(D8:D10)/1000 -> 2.2673333 | F8: 2235 | G8: =AVERAGE(F8:F10)/1000 -> 2.2203333 | H8: 2193 | I8: =AVERAGE(H8:H10)/1000 -> 2.186 | J8: 2273 | K8: =AVERAGE(J8:J10)/1000 -> 2.264 | L8: 2279 | M8: =AVERAGE(L8:L10)/1000 -> 2.253
B9: 2493 | D9: 2278 | F9: 2210 | H9: 2182 | J9: 2248 | L9: 2247
B10: 2450 | D10: 2258 | F10: 2216 | H10: 2183 | J10: 2271 | L10: 2233
A11: 28 | B11: 2396 | C11: =AVERAGE(B11:B13)/1000 -> 2.3843333 | D11: 2373 | E11: =AVERAGE(D11:D13)/1000 -> 2.3496667 | F11: 2249 | G11: =AVERAGE(F11:F13)/1000 -> 2.253 | H11: 2182 | I11: =AVERAGE(H11:H13)/1000 -> 2.1816667 | J11: 2198 | K11: =AVERAGE(J11:J13)/1000 -> 2.1906667 | L11: 2199 | M11: =AVERAGE(L11:L13)/1000 -> 2.184
B12: 2369 | D12: 2341 | F12: 2243 | H12: 2174 | J12: 2190 | L12: 2164
B13: 2388 | D13: 2335 | F13: 2267 | H13: 2189 | J13: 2184 | L13: 2189
A14: COMPRESSION TEST
A15: 7 | B15: 48.536 | C15: =AVERAGE(B15:B17) -> 48.128667 | D15: 30.353 | E15: =AVERAGE(D15:D17) -> 30.985333 | F15: 24.963 | G15: =AVERAGE(F15:F17) -> 25.482333 | H15: 22.613 | I15: =AVERAGE(H15:H17) -> 21.890333 | J15: 20.623 | K15: =AVERAGE(J15:J17) -> 22.018333 | L15: 22.486 | M15: =AVERAGE(L15:L17) -> 23.265
B16: 46.803 | D16: 32.062 | F16: 27.755 | H16: 21.578 | J16: 22.568 | L16: 24.044
B17: 49.047 | D17: 30.541 | F17: 23.729 | H17: 21.48 | J17: 22.864 | L17: 23.245
A18: 14 | B18: 52.96 | C18: =AVERAGE(B18:B20) -> 53.783333 | D18: 29.7 | E18: =AVERAGE(D18:D20) -> 29.782 | F18: 21.262 | G18: =AVERAGE(F18:F20) -> 20.259 | H18: 21.814 | I18: =AVERAGE(H18:H20) -> 20.972333 | J18: 23.743 | K18: =AVERAGE(J18:J20) -> 23.421667 | L18: 23.852 | M18: =AVERAGE(L18:L19) -> 23.483
B19: 53.874 | D19: 30.08 | F19: 20.074 | H19: 21.228 | J19: 22.54 | L19: 23.114
B20: 54.516 | D20: 29.566 | F20: 19.441 | H20: 19.875 | J20: 23.982 | L20: 23.083
A21: 28 | B21: 52.028 | C21: =AVERAGE(B21:B23) -> 52.921 | D21: 32.571 | E21: =AVERAGE(D21:D23) -> 32.293 | F21: 26.56 | G21: =AVERAGE(F21:F23) -> 28.212 | H21: 27.635 | I21: =AVERAGE(H21:H23) -> 25.930667 | J21: 24.25 | K21: =AVERAGE(J21:J23) -> 25.063333 | L21: 23.971 | M21: =AVERAGE(L21:L22) -> 23.296
B22: 54.602 | D22: 30.977 | F22: 29.231 | H22: 24.091 | J22: 25.854 | L22: 22.621
B23: 52.133 | D23: 33.331 | F23: 28.845 | H23: 26.066 | J23: 25.086 | L23: 23.276
A24: SPLIT DENSITY
A25: 28 | B25: 3928 | C25: =AVERAGE(B25:B27)/(PI()*10*10*20/4) -> 2.5029767 | D25: 3800 | E25: =AVERAGE(D25:D27)/(PI()*10*10*20/4) -> 2.4166087 | F25: 3757 | G25: =AVERAGE(F25:F27)/(PI()*10*10*20/4) -> 2.3917805 | H25: 3659 | I25: =AVERAGE(H25:H27)/(PI()*10*10*20/4) -> 2.3349091 | J25: 3643 | K25: =AVERAGE(J25:J27)/(PI()*10*10*20/4) -> 2.3223889 | L25: 3601 | M25: =AVERAGE(L25:L27)/(PI()*10*10*20/4) -> 2.2911946
B26: 3929 | D26: 3798 | F26: 3770 | H26: 3676 | J26: 3660 | L26: 3597
B27: 3938 | D27: 3790 | F27: 3744 | H27: 3668 | J27: 3641 | L27: 3599
A28: SPLITING TEST
A29: 28 | B29: 3.554 | C29: =AVERAGE(B29:B31) -> 3.5273333 | D29: 3.448 | E29: =AVERAGE(D29:D31) -> 3.465 | F29: 3.82 | G29: =AVERAGE(F29:F31) -> 3.429 | H29: 3.425 | I29: =AVERAGE(H29:H31) -> 3.4306667 | J29: 2.427 | K29: =AVERAGE(J29:J31) -> 2.486 | L29: 2.469 | M29: =AVERAGE(L29:L31) -> 2.4123333
B30: 3.451 | D30: 3.535 | F30: 3.335 | H30: 3.446 | J30: 2.447 | L30: 2.316
B31: 3.577 | D31: 3.412 | F31: 3.132 | H31: 3.421 | J31: 2.584 | L31: 2.452
A32: FLEXURAL DENSITY
A33: 28 | B33: =9046/(10*10*35) -> 2.5845714 | D33: =8922/(10*10*35) -> 2.5491429 | F33: =8740/(10*10*35) -> 2.4971429 | H33: =8138/(10*10*35) -> 2.3251429 | J33: =8162/(10*10*35) -> 2.332 | L33: 2.28
A34: FLEXURAL TEST
A35: 28 | B35: 9.362 | C35: 9.362 | D35: 8.089 | E35: 8.089 | F35: 7.676 | G35: 7.676 | H35: 6.652 | I35: 6.652 | J35: 6.184 | K35: 6.184 | L35: 5.89 | M35: 5.89
A36: % | C36: 0 | E36: 1 | G36: 2 | I36: 3 | K36: 4 | M36: 5
A37: Porosity | C37: =Absorpsion!F8 -> 0.032371581 | E37: =Absorpsion!J8 -> 0.048718914 | G37: =Absorpsion!N8 -> 0.052069149 | I37: =Absorpsion!R8 -> 0.058312627 | K37: =Absorpsion!V8 -> 0.054661696 | M37: =Absorpsion!Z8 -> 0.061766316

Sheet Specific Gravity
A1: Specific Gravity for Fine Aggregates | G1: Specific Gravity for Fine Aggregates | K1: Zerwal
A2: Sample No. | B2: 1 | C2: 2 | D2: 3 | H2: Trial 1 | I2: Trial 2 | J2: Average
A3: Mass of Pyconometer (g) | B3: 685 | C3: 685 | D3: 685 | G3: Pycnometer Weight (M0) | H3: =H4-500 -> 685 | I3: =I4-500 -> 685 | J3: =AVERAGE(H3:I3) -> 685
A4: Mass of Pyconometer + Sand (g) | B4: 1185 | C4: 1186 | D4: 1187 | G4: Mat + Pycnometer (M1) | H4: 1185 | I4: 1185 | J4: =AVERAGE(H4:I4) -> 1185
A5: Mass of Pyconometer + Sand + Water (g) | B5: 1851 | C5: 1847 | D5: 1853 | G5: Mat + Pycnometer + Water (M2) | H5: 1851 | I5: 1847 | J5: =AVERAGE(H5:I5) -> 1849
A6: Mass of Pyconometer + Water (g) | B6: 1560 | C6: 1561 | D6: 1558 | G6: Mat oven dry (M3) | H6: 473 | I6: 470 | J6: =AVERAGE(H6:I6) -> 471.5
A7: Mass of Oven-dry Sample (g) | B7: 473 | C7: 470 | D7: 476 | G7: Pycnometer + water (M4) | H7: 1560 | I7: 1561 | J7: =AVERAGE(H7:I7) -> 1560.5
G8: Specific gravity SSD (M1-M0)/[(M4-M0)-(M2-M1) | H8: =(H4-H3)/((H7-H3)-(H5-H4)) -> 2.3923445 | I8: =(I4-I3)/((I7-I3)-(I5-I4)) -> 2.3364486 | J8: =AVERAGE(H8:I8) -> 2.3643965
G9: Specific gravity (Oven dry) (M3/[(M4-M0)-(M2-M1) | H9: =H6/((H7-H3)-(H5-H4)) -> 2.2631579 | I9: =I6/((I7-I3)-(I5-I4)) -> 2.1962617 | J9: =AVERAGE(H9:I9) -> 2.2297098
G10: Water absorption ((M1-M0-M3)*100)/M3 | H10: =((H4-H3-H6)/H6)*100 -> 5.7082452 | I10: =((I4-I3-I6)/I6)*100 -> 6.3829787 | J10: =AVERAGE(H10:I10) -> 6.045612
G13: Specific Gravity for Coarse Aggregate
A14: Specific Gravity for Coarse Aggregate | H14: Trial 1 | I14: Trial 2 | J14: Average
A15: Mass of Sample: 2000 g | G15: Weight of empty basket in air (Mair) (g) | H15: 438 | I15: 438 | J15: =AVERAGE(H15:I15) -> 438
A16: Sample No. | B16: 1 | C16: 2 | D16: 3 | G16: Material + Basket in air (Mair') (g) | H16: 2438 | I16: 2438 | J16: =AVERAGE(H16:I16) -> 2438
A17: Mass of Basket in Air (g) | B17: 438 | C17: 438 | D17: 438 | G17: Material (M1 = Mair' - Mair) (g) | H17: 2000 | I17: 2000 | J17: =AVERAGE(H17:I17) -> 2000
A18: Mass of Basket in Water | B18: 395 | C18: 395 | D18: 395 | G18: Empty Basket in water (Mw) (g) | H18: 395 | I18: 395 | J18: =AVERAGE(H18:I18) -> 395
A19: Mass of Basket + Aggregate in Air | B19: 2800.5 | C19: 2799.5 | D19: 2800.5 | G19: Basket + Material in water (Mw') (g) | H19: 1607.5 | I19: 1606.5 | J19: =AVERAGE(H19:I19) -> 1607
A20: Mass of Basket + Aggregate in Water | B20: 1607.5 | C20: 1606.5 | D20: 1609.5 | G20: Material in water (M2 = Mw - Mw') (g) | H20: =H19-H18 -> 1212.5 | I20: =I19-I18 -> 1211.5 | J20: =AVERAGE(H20:I20) -> 1212
A21: Mass of Oven-dry Sample | B21: 1926 | C21: 1923 | D21: 1930 | G21: Material oven dry (M3) (g) | H21: 1926 | I21: 1923 | J21: =AVERAGE(H21:I21) -> 1924.5
G22: Specific gravity SSD (M1/(M1-M2)) | H22: =H17/(H17-H20) -> 2.5396825 | I22: =I17/(I17-I20) -> 2.5364616 | J22: =AVERAGE(H22:I22) -> 2.5380721
G23: Specific gravity (Oven dry) (M3/(M1-M2)) | H23: =H21/(H17-H20) -> 2.4457143 | I23: =I21/(I17-I20) -> 2.4388079 | J23: =AVERAGE(H23:I23) -> 2.4422611
G24: Apparent specific gravity (M3/(M3-M2)) | H24: =H21/(H21-H20) -> 2.6993693 | I24: =I21/(I21-I20) -> 2.7027407 | J24: =AVERAGE(H24:I24) -> 2.701055
G25: Water absorption ((M1-M3)*100)/M3 | H25: =((H17-H21)*100)/H21 -> 3.8421599 | I25: =((I17-I21)*100)/I21 -> 4.0041602 | J25: =AVERAGE(H25:I25) -> 3.92316
A30: Emma
A31: Specific Gravity for Fine Aggregates
A32: Mass of Pyconometer (g) | B32: 685 | C32: 685 | D32: 685
A33: Mass of Pyconometer + Sand (g) | B33: 1185 | C33: 1186 | D33: 1187
A34: Mass of Pyconometer + Sand + Water (g) | B34: 1851 | C34: 1847 | D34: 1853
A35: Mass of Pyconometer + Water (g) | B35: 1560 | C35: 1561 | D35: 1558
A36: Mass of Oven-dry Sample (g) | B36: 473 | C36: 470 | D36: 476
A38: Specific Gravity for Coarse Aggregate
A39: Mass of Sample: 2000 g
A40: Sample No. | B40: 1 | C40: 2 | D40: 3
A41: Mass of Basket in Air (g) | B41: 438 | C41: 438 | D41: 438
A42: Mass of Basket in Water | B42: 395 | C42: 395 | D42: 395
A43: Mass of Basket + Aggregate in Air | B43: 2800.5 | C43: 2799.5 | D43: 2800.5
A44: Mass of Basket + Aggregate in Water | B44: 1607.5 | C44: 1606.5 | D44: 1609.5
A45: Mass of Oven-dry Sample | B45: 1926 | C45: 1923 | D45: 1930

Sheet Bulk Density
A2: BULK DENSITY OF CORSE AGGREGATE | G2: BULK DENSITY OF FINE AGGREGATE
B3: Trial 1 | C3: Trial 2 | D3: Average | G3: Trial 1 | H3: Trial 2 | I3: Average
A4: Container weight (g) | B4: 3363 | C4: 3363 | D4: =AVERAGE(B4:C4) -> 3363 | F4: Container weight (g) | G4: 3363 | H4: 3363 | I4: =AVERAGE(G4:H4) -> 3363
A5: Container + Water (g) | B5: 5220 | C5: 5220 | D5: =AVERAGE(B5:C5) -> 5220 | F5: Container + Water (g) | G5: 5220 | H5: 5220 | I5: =AVERAGE(G5:H5) -> 5220
A6: Container Volume (cm3) | B6: =B5-B4 -> 1857 | C6: =C5-C4 -> 1857 | D6: =AVERAGE(B6:C6) -> 1857 | F6: Container Volume (cm3) | G6: =G5-G4 -> 1857 | H6: =H5-H4 -> 1857 | I6: =AVERAGE(G6:H6) -> 1857
A7: Container + CA | B7: 6118 | C7: 6124 | D7: =AVERAGE(B7:C7) -> 6121 | F7: Container + FA | G7: 6374 | H7: 6388 | I7: =AVERAGE(G7:H7) -> 6381
A8: CA weight | B8: =B7-B4 -> 2755 | C8: =C7-C4 -> 2761 | D8: =AVERAGE(B8:C8) -> 2758 | F8: FA weight | G8: =G7-G4 -> 3011 | H8: =H7-H4 -> 3025 | I8: =AVERAGE(G8:H8) -> 3018
A9: CA bulk density | B9: =B8/B6 -> 1.4835757 | C9: =C8/C6 -> 1.4868067 | D9: =AVERAGE(B9:C9) -> 1.4851912 | F9: CA bulk density | G9: =G8/G6 -> 1.6214324 | H9: =H8/H6 -> 1.6289715 | I9: =AVERAGE(G9:H9) -> 1.6252019

Sheet Compacted Density MDD
B1: FA & CA mix Density
A2: Container weight | C2: 1535 | D2: g
A3: Container + water | C3: 3633 | D3: g
A4: Container volume | C4: =C3-C2 -> 2098 | D4: ml
B6: Percentage | C6: Mass | D6: Density
B7: 0 | C7: 3136 | D7: =C7/$C$4 -> 1.4947569
B8: 5 | C8: 3165 | D8: =C8/$C$4 -> 1.5085796
B9: 10 | C9: 3298 | D9: =C9/$C$4 -> 1.5719733
B10: 15 | C10: 3489 | D10: =C10/$C$4 -> 1.6630124
B11: 20 | C11: 3497 | D11: =C11/$C$4 -> 1.6668255
B12: 25 | C12: 3655 | D12: =C12/$C$4 -> 1.7421354
B13: 30 | C13: 3751 | D13: =C13/$C$4 -> 1.7878932
B14: 35 | C14: 3769 | D14: =C14/$C$4 -> 1.7964728
B15: 40 | C15: 3769 | D15: =C15/$C$4 -> 1.7964728
B16: 45 | C16: 3759 | D16: =C16/$C$4 -> 1.7917064
B17: 50 | C17: 3694 | D17: =C17/$C$4 -> 1.7607245

Sheet AIV
A1: Aggregate Impact Value | B1: Zerwal
A2: Sample No. | B2: 1 | C2: 2 | D2: 3 | E2: Average
A3: Total Mass of Sample m1 (g) | B3: 500 | C3: 500 | D3: 500
A4: Mass Retained on the sieve m2 (g) | B4: 473 | C4: 472 | D4: 474
A5: Mass Passing Separation Sieve (p) | B5: 26 | C5: 27 | D5: 25
A6: Loss (g) | B6: =B3-(B4+B5) -> 1 | C6: =C3-(C4+C5) -> 1 | D6: =D3-(D4+D5) -> 1
A7: AIV = (px100)/m1 | B7: =B5/B3 -> 0.052 | C7: =C5/C3 -> 0.054 | D7: =D5/D3 -> 0.05 | E7: =AVERAGE(B7:D7) -> 0.052
A10: Emma
A11: Aggregate Impact Value
A12: Sample No. | B12: 1 | C12: 2 | D12: 3 | E12: Average
A13: Total Mass of Sample (m1) | B13: 500 g | C13: 500 g | D13: 500 g
A17: Mass Retained on the sieve (m2) | B17: 473 | C17: 475 | D17: 472
A18: Mass Passing Separation Sieve (p) | B18: 26 | C18: 24 | D18: 27
A19: Loss (g) | B19: 1 | C19: 1 | D19: 1
A20: AIV = (px100)/m1 | E20: 0.0513

Sheet ACV
A1: Aggregate Crushing Value (ACV) Results | B1: Zerwal
A2: Sample No. | B2: 1 | C2: 2 | D2: Average
A3: Total Mass of Sample m1 (g) | B3: 2488 | C3: 2533
A4: Mass Retained on 2.36mm sieve m2 (g) | B4: 2144 | C4: 2173
A5: Mass Passing 2.36mm Sieve (m1-m2 ) | B5: 343 | C5: 358
A6: Loss (g) | B6: =B3-(B4+B5) -> 1 | C6: =C3-(C4+C5) -> 2
A7: AIV = (px100)/m1 | B7: =(B5/B3) -> 0.13786174 | C7: =(C5/C3) -> 0.14133439 | D7: =AVERAGE(B7:C7) -> 0.13959806
A15: Emma
A16: Aggregate Crushing Value (ACV) Results
A17: Sample No. | B17: 1 | C17: 2 | D17: 3 | E17: Average
A18: Total Mass of Sample (m1) | B18: 2797 g | C18: 2810 g | D18: 2789 g
A19: Mass Retained on 2.36mm sieve (m2) | B19: 2680,9 | C19: 2692.4 | D19: 2673.2
A20: Mass Passing 2.36mm Sieve (m1-m2 ) | B20: 114.1 | C20: 115.8 | D20: 114.3
A21: Loss (g) | B21: 2 | C21: 1.8 | D21: 1.5
A22: AIV = (px100)/m1 | E22: 0.041

Sheet PSD
A1: Sieve Analysis for Fine Aggregate
A2: Mass of Each Sample: 2000 g
A3: Total Mass of Sample (g) | B3: Sample 1 | G3: Sample 2 | K3: Sample 3
A4: Sieve (mm) | B4: Mass of sieve (g) | C4: Mass Retained (Sieve + Aggregate) (g) | D4: Cumulated | E4: % Retained | F4: % Passing | G4: Mass Retained (Sieve + Aggregate) (g) | H4: Cumulated | I4: % Retained | J4: % Passing | K4: Mass Retained (Sieve + Aggregate) (g) | L4: Cumulated | M4: % Retained | N4: % Passing
A5: 5 | B5: 831 | C5: 849 | D5: =C5-B5 -> 18 | E5: =(D5/$D$12)*100 -> 0.90180361 | F5: =$E$12-E5 -> 99.098196 | G5: 852 | H5: =G5-B5 -> 21 | I5: =(H5/$H$12)*100 -> 1.0510511 | J5: =$I$12-I5 -> 98.948949 | K5: 860 | L5: =K5-B5 -> 29 | M5: =(L5/$L$12)*100 -> 1.4514515 | N5: =$M$12-M5 -> 98.548549
A6: 2.36 | B6: 808 | C6: 886 | D6: =D5+C6-B6 -> 96 | E6: =(D6/$D$12)*100 -> 4.8096192 | F6: =$E$12-E6 -> 95.190381 | G6: 886 | H6: =H5+G6-B6 -> 99 | I6: =(H6/$H$12)*100 -> 4.954955 | J6: =$I$12-I6 -> 95.045045 | K6: 912 | L6: =L5+K6-B6 -> 133 | M6: =(L6/$L$12)*100 -> 6.6566567 | N6: =$M$12-M6 -> 93.343343
A7: 1.25 | B7: 785 | C7: 1353 | D7: =D6+C7-B7 -> 664 | E7: =(D7/$D$12)*100 -> 33.266533 | F7: =$E$12-E7 -> 66.733467 | G7: 1143 | H7: =H6+G7-B7 -> 457 | I7: =(H7/$H$12)*100 -> 22.872873 | J7: =$I$12-I7 -> 77.127127 | K7: 1220 | L7: =L6+K7-B7 -> 568 | M7: =(L7/$L$12)*100 -> 28.428428 | N7: =$M$12-M7 -> 71.571572
A8: 0.6 | B8: 758 | C8: 1573 | D8: =D7+C8-B8 -> 1479 | E8: =(D8/$D$12)*100 -> 74.098196 | F8: =$E$12-E8 -> 25.901804 | G8: 1310 | H8: =H7+G8-B8 -> 1009 | I8: =(H8/$H$12)*100 -> 50.500501 | J8: =$I$12-I8 -> 49.499499 | K8: 1350 | L8: =L7+K8-B8 -> 1160 | M8: =(L8/$L$12)*100 -> 58.058058 | N8: =$M$12-M8 -> 41.941942
A9: 0.3 | B9: 709 | C9: 1132 | D9: =D8+C9-B9 -> 1902 | E9: =(D9/$D$12)*100 -> 95.290581 | F9: =$E$12-E9 -> 4.7094188 | G9: 1443 | H9: =H8+G9-B9 -> 1743 | I9: =(H9/$H$12)*100 -> 87.237237 | J9: =$I$12-I9 -> 12.762763 | K9: 1315 | L9: =L8+K9-B9 -> 1766 | M9: =(L9/$L$12)*100 -> 88.388388 | N9: =$M$12-M9 -> 11.611612
A10: 0.18 | B10: 711 | C10: 776 | D10: =D9+C10-B10 -> 1967 | E10: =(D10/$D$12)*100 -> 98.547094 | F10: =$E$12-E10 -> 1.4529058 | G10: 877 | H10: =H9+G10-B10 -> 1909 | I10: =(H10/$H$12)*100 -> 95.545546 | J10: =$I$12-I10 -> 4.4544545 | K10: 864 | L10: =L9+K10-B10 -> 1919 | M10: =(L10/$L$12)*100 -> 96.046046 | N10: =$M$12-M10 -> 3.953954
A11: 0.075 | B11: 580 | C11: 607 | D11: =D10+C11-B11 -> 1994 | E11: =(D11/$D$12)*100 -> 99.8998 | F11: =$E$12-E11 -> 0.1002004 | G11: 665 | H11: =H10+G11-B11 -> 1994 | I11: =(H11/$H$12)*100 -> 99.7998 | J11: =$I$12-I11 -> 0.2002002 | K11: 653 | L11: =L10+K11-B11 -> 1992 | M11: =(L11/$L$12)*100 -> 99.6997 | N11: =$M$12-M11 -> 0.3003003
A12: Pan | B12: 712 | C12: 714 | D12: =D11+C12-B12 -> 1996 | E12: =(D12/$D$12)*100 -> 100 | F12: =$E$12-E12 -> 0 | G12: 716 | H12: =H11+G12-B12 -> 1998 | I12: =(H12/$H$12)*100 -> 100 | J12: =$I$12-I12 -> 0 | K12: 718 | L12: =L11+K12-B12 -> 1998 | M12: =(L12/$L$12)*100 -> 100 | N12: =$M$12-M12 -> 0
D13: Finesse module | E13: =(E10+E9+E8+E7+E6+E5)/100 -> 3.0691383 | H13: Finesse module | I13: =(I10+I9+I8+I7+I6+I5)/100 -> 2.6216216 | L13: Finesse module | M13: =(M10+M9+M8+M7+M6+M5)/100 -> 2.7902903
A14: Sieve Analysis for Coarse Aggregate | H14: Mean Finess module | I14: =(E13+I13+M13)/3 -> 2.8270167
A15: Mass of Each Sample: 3000 g
A16: Total Mass of Sample (g) | B16: Sample 1 | G16: Sample 2 | K16: Sample 3
A17: Sieve (mm) | B17: Mass of sieve (g) | C17: Mass Retained (Sieve + Aggregate) (g) | D17: Cumulated | E17: % Retained | F17: % Passing | G17: Mass Retained (Sieve + Aggregate) (g) | H17: Cumulated | I17: % Retained | J17: % Passing | K17: Mass Retained (Sieve + Aggregate) (g) | L17: Cumulated | M17: % Retained | N17: % Passing
A18: 20 | B18: 985 | C18: 985 | D18: =C18-B18 -> 0 | E18: =(D18/$D$25)*100 -> 0 | F18: =$E$25-E18 -> 100 | G18: 985 | H18: =G18-B18 -> 0 | I18: =(H18/$H$25)*100 -> 0 | J18: =$I$25-I18 -> 100 | K18: 985 | L18: =K18-B18 -> 0 | M18: =(L18/$L$25)*100 -> 0 | N18: =$M$25-M18 -> 100
A19: 16 | B19: 1027 | C19: 1027 | D19: =D18+C19-B19 -> 0 | E19: =(D19/$D$25)*100 -> 0 | F19: =$E$12-E19 -> 100 | G19: 1027 | H19: =H18+G19-B19 -> 0 | I19: =(H19/$H$25)*100 -> 0 | J19: =$I$25-I19 -> 100 | K19: 1027 | L19: =L18+K19-B19 -> 0 | M19: =(L19/$L$25)*100 -> 0 | N19: =$M$25-M19 -> 100 | Q19: =K19-B19 -> 0
A20: 14 | B20: 1084 | C20: 1115 | D20: =D19+C20-B20 -> 31 | E20: =(D20/$D$25)*100 -> 1.0333333 | F20: =$E$12-E20 -> 98.966667 | G20: 1101 | H20: =H19+G20-B20 -> 17 | I20: =(H20/$H$25)*100 -> 0.56666667 | J20: =$I$25-I20 -> 99.433333 | K20: 1100 | L20: =L19+K20-B20 -> 16 | M20: =(L20/$L$25)*100 -> 0.53333333 | N20: =$M$25-M20 -> 99.466667 | Q20: =K20+Q19 -> 1100
A21: 12.5 | B21: 990 | C21: 1152 | D21: =D20+C21-B21 -> 193 | E21: =(D21/$D$25)*100 -> 6.4333333 | F21: =$E$12-E21 -> 93.566667 | G21: 1146 | H21: =H20+G21-B21 -> 173 | I21: =(H21/$H$25)*100 -> 5.7666667 | J21: =$I$25-I21 -> 94.233333 | K21: 1164 | L21: =L20+K21-B21 -> 190 | M21: =(L21/$L$25)*100 -> 6.3333333 | N21: =$M$25-M21 -> 93.666667
A22: 10 | B22: 815 | C22: 1614 | D22: =D21+C22-B22 -> 992 | E22: =(D22/$D$25)*100 -> 33.066667 | F22: =$E$12-E22 -> 66.933333 | G22: 1520 | H22: =H21+G22-B22 -> 878 | I22: =(H22/$H$25)*100 -> 29.266667 | J22: =$I$25-I22 -> 70.733333 | K22: 1509 | L22: =L21+K22-B22 -> 884 | M22: =(L22/$L$25)*100 -> 29.466667 | N22: =$M$25-M22 -> 70.533333
A23: 5 | B23: 831 | C23: 2801 | D23: =D22+C23-B23 -> 2962 | E23: =(D23/$D$25)*100 -> 98.733333 | F23: =$E$12-E23 -> 1.2666667 | G23: 2848 | H23: =H22+G23-B23 -> 2895 | I23: =(H23/$H$25)*100 -> 96.5 | J23: =$I$25-I23 -> 3.5 | K23: 2910 | L23: =L22+K23-B23 -> 2963 | M23: =(L23/$L$25)*100 -> 98.766667 | N23: =$M$25-M23 -> 1.2333333
A24: 2.36 | B24: 808 | C24: 845 | D24: =D23+C24-B24 -> 2999 | E24: =(D24/$D$25)*100 -> 99.966667 | F24: =$E$12-E24 -> 0.033333333 | G24: 911 | H24: =H23+G24-B24 -> 2998 | I24: =(H24/$H$25)*100 -> 99.933333 | J24: =$I$25-I24 -> 0.066666667 | K24: 844 | L24: =L23+K24-B24 -> 2999 | M24: =(L24/$L$25)*100 -> 99.966667 | N24: =$M$25-M24 -> 0.033333333
A25: Pan | B25: 712 | C25: 713 | D25: =D24+C25-B25 -> 3000 | E25: =(D25/$D$25)*100 -> 100 | F25: =$E$12-E25 -> 0 | G25: 714 | H25: =H24+G25-B25 -> 3000 | I25: =(H25/$H$25)*100 -> 100 | J25: =$I$25-I25 -> 0 | K25: 713 | L25: =L24+K25-B25 -> 3000 | M25: =(L25/$L$25)*100 -> 100 | N25: =$M$25-M25 -> 0
A28: Sieve Size (mm) | B28: Upper Limit | C28: Lower Limit | D28: Commulative % Passing | F28: Sieve Size (mm) | G28: Upper Limit | H28: Lower Limit | I28: Commulative % Passing
A29: mm | B29: g | C29: g | D29: % | F29: 16 | G29: 100 | H29: 100 | I29: =AVERAGE(F19,J19,N19) -> 100
A30: 9.5 | B30: 100 | C30: 100 | D30: 100 | F30: 14 | G30: 100 | H30: 100 | I30: =AVERAGE(F20,J20,N20) -> 99.288889
A31: 4.75 | B31: 100 | C31: 95 | D31: =AVERAGE(N5,J5) -> 98.748749 | F31: 12.5 | G31: 100 | H31: 90 | I31: =AVERAGE(F21,J21,N21) -> 93.822222
A32: 2.36 | B32: 100 | C32: 80 | D32: =AVERAGE(N6,J6) -> 94.194194 | F32: 9.5 | G32: 70 | H32: 40 | I32: =AVERAGE(F22,J22,N22) -> 69.4
A33: 1.18 | B33: 85 | C33: 50 | D33: =AVERAGE(N7,J7) -> 74.349349 | F33: 5 | G33: 15 | H33: 0 | I33: =AVERAGE(F23,J23,N23) -> 2
A34: 0.6 | B34: 60 | C34: 25 | D34: =AVERAGE(N8,J8) -> 45.720721 | F34: 2.36 | G34: 5 | H34: 0 | I34: =AVERAGE(F24,J24,N24) -> 0.044444444
A35: 0.3 | B35: 30 | C35: 10 | D35: =AVERAGE(N9,J9) -> 12.187187 | G35: 0 | H35: 0 | I35: 0
A36: 0.15 | B36: 10 | C36: 2 | D36: =AVERAGE(N10,J10) -> 4.2042042
A37: 0.075 | B37: 2 | C37: 0 | D37: =AVERAGE(N11,J11) -> 0.25025025
B38: 0 | C38: 0 | D38: =AVERAGE(N12,J12) -> 0
G64: Finesse Modulus | H64: 2.81
G65: Type of sand | H65: Fineness modulus range
G66: Fine sand | H66: 2.2 – 2.6
G67: Medium sand | H67: 2.6 – 2.9
...

Sheet Absorpsion
C1: 0 | G1: 1 | K1: 2 | O1: 3 | S1: 4 | W1: 5
A2: Mon 29/09/2025 | C2: 2337 | D2: 2311 | E2: 2453 | F2: =AVERAGE(C2:E2) -> 2367 | G2: 2276 | H2: 2273 | I2: 2272 | J2: =AVERAGE(G2:I2) -> 2273.6667 | K2: 2284 | L2: 2257 | M2: 2169 | N2: =AVERAGE(K2:M2) -> 2236.6667 | O2: 2154 | P2: 2174 | Q2: 2130 | R2: =AVERAGE(O2:Q2) -> 2152.6667 | S2: 2086 | T2: 2206 | U2: 2209 | V2: =AVERAGE(S2:U2) -> 2167 | W2: 2206 | X2: 2165 | Z2: =AVERAGE(W2:X2) -> 2185.5
A3: Tue 30/09/2025 | C3: 2272 | U3: 2101 | W3: 2082
C4: =(C2-C3)/C3*100 -> 2.8609155 | U4: =(U2-U3)/U3*100 -> 5.1404093 | W4: =(W2-W3)/W3*100 -> 5.9558117
A5: Wed 01/10/2025 | C5: 2250 | D5: 2219 | E5: 2359 | F5: =AVERAGE(C5:E5) -> 2276 | G5: 2161 | H5: 2154 | I5: 2151 | J5: =AVERAGE(G5:I5) -> 2155.3333 | K5: 2155 | L5: 2130 | M5: 2051 | N5: =AVERAGE(K5:M5) -> 2112 | O5: 2021 | P5: 2043 | Q5: 2006 | R5: =AVERAGE(O5:Q5) -> 2023.3333 | S5: 1966 | T5: 2077 | U5: 2083 | V5: =AVERAGE(S5:U5) -> 2042 | W5: 2068 | X5: 2028 | Z5: =AVERAGE(W5:X5) -> 2048
A6: Thu 02/10/2025
A7: Fri 03/10/2025 | C7: 2322 | D7: 2292 | E7: 2435 | F7: =AVERAGE(C7:E7) -> 2349.6667 | G7: 2263 | H7: 2258 | I7: 2260 | J7: =AVERAGE(G7:I7) -> 2260.3333 | K7: 2269 | L7: 2241 | M7: 2156 | N7: =AVERAGE(K7:M7) -> 2222 | O7: 2140 | P7: 2164 | Q7: 2120 | R7: =AVERAGE(O7:Q7) -> 2141.3333 | S7: 2071 | T7: 2192 | U7: 2198 | V7: =AVERAGE(S7:U7) -> 2153.6667 | W7: 2196 | X7: 2153 | Z7: =AVERAGE(W7:X7) -> 2174.5
A8: Porosity | C8: =(C7-C5)/C5 -> 0.032 | D8: =(D7-D5)/D5 -> 0.032897702 | E8: =(E7-E5)/E5 -> 0.032217041 | F8: =AVERAGE(C8:E8) -> 0.032371581 | G8: =(G7-G5)/G5 -> 0.04720037 | H8: =(H7-H5)/H5 -> 0.048282266 | I8: =(I7-I5)/I5 -> 0.050674105 | J8: =AVERAGE(G8:I8) -> 0.048718914 | K8: =(K7-K5)/K5 -> 0.052900232 | L8: =(L7-L5)/L5 -> 0.052112676 | M8: =(M7-M5)/M5 -> 0.051194539 | N8: =AVERAGE(K8:M8) -> 0.052069149 | O8: =(O7-O5)/O5 -> 0.058881742 | P8: =(P7-P5)/P5 -> 0.059226628 | Q8: =(Q7-Q5)/Q5 -> 0.056829511 | R8: =AVERAGE(O8:Q8) -> 0.058312627 | S8: =(S7-S5)/S5 -> 0.053407935 | T8: =(T7-T5)/T5 -> 0.05536832 | U8: =(U7-U5)/U5 -> 0.055208833 | V8: =AVERAGE(S8:U8) -> 0.054661696 | W8: =(W7-W5)/W5 -> 0.061895551 | X8: =(X7-X5)/X5 -> 0.061637081 | Z8: =AVERAGE(W8:X8) -> 0.061766316
A9: Standard Deviation | C9: =_xlfn.STDEV.P(C8:E8) -> 0.00038242994 | G9: =_xlfn.STDEV.P(G8:I8) -> 0.0014513682 | K9: =_xlfn.STDEV.P(K8:M8) -> 0.00069702602 | O9: =_xlfn.STDEV.P(O8:Q8) -> 0.0010581305 | S9: =_xlfn.STDEV.P(S8:U8) -> 0.00088893069 | W9: =_xlfn.STDEV.P(W8:X8) -> 0.00012923519
C11: =(C5-C7)/C5 -> -0.032 | D11: =(D5-D7)/D5 -> -0.032897702 | E11: =(E5-E7)/E5 -> -0.032217041 | F11: =(F5-F7)/F5 -> -0.032366725 | G11: =(G5-G7)/G5 -> -0.04720037 | H11: =(H5-H7)/H5 -> -0.048282266 | I11: =(I5-I7)/I5 -> -0.050674105 | J11: =(J5-J7)/J5 -> -0.048716363 | ... Z11: =(Z5-Z7)/Z5 -> -0.061767578
